[2024-01-16T12:30:02.809+0200] {taskinstance.py:1957} INFO - Dependencies all met for dep_context=non-requeueable deps ti=<TaskInstance: execute_python_pipeline.task_1 manual__2024-01-16T10:30:00.071782+00:00 [queued]>
[2024-01-16T12:30:02.814+0200] {taskinstance.py:1957} INFO - Dependencies all met for dep_context=requeueable deps ti=<TaskInstance: execute_python_pipeline.task_1 manual__2024-01-16T10:30:00.071782+00:00 [queued]>
[2024-01-16T12:30:02.815+0200] {taskinstance.py:2171} INFO - Starting attempt 1 of 1
[2024-01-16T12:30:02.830+0200] {taskinstance.py:2192} INFO - Executing <Task(PythonOperator): task_1> on 2024-01-16 10:30:00.071782+00:00
[2024-01-16T12:30:02.833+0200] {standard_task_runner.py:60} INFO - Started process 7800 to run task
[2024-01-16T12:30:02.835+0200] {standard_task_runner.py:87} INFO - Running: ['airflow', 'tasks', 'run', 'execute_python_pipeline', 'task_1', 'manual__2024-01-16T10:30:00.071782+00:00', '--job-id', '97', '--raw', '--subdir', 'DAGS_FOLDER/executing_python_pipeline.py', '--cfg-path', '/tmp/tmpga8i6sih']
[2024-01-16T12:30:02.837+0200] {standard_task_runner.py:88} INFO - Job 97: Subtask task_1
[2024-01-16T12:30:02.872+0200] {task_command.py:423} INFO - Running <TaskInstance: execute_python_pipeline.task_1 manual__2024-01-16T10:30:00.071782+00:00 [running]> on host DESKTOP-9NHC01K.
[2024-01-16T12:30:02.929+0200] {taskinstance.py:2481} INFO - Exporting env vars: AIRFLOW_CTX_DAG_OWNER='airflow' AIRFLOW_CTX_DAG_ID='execute_python_pipeline' AIRFLOW_CTX_TASK_ID='task_1' AIRFLOW_CTX_EXECUTION_DATE='2024-01-16T10:30:00.071782+00:00' AIRFLOW_CTX_TRY_NUMBER='1' AIRFLOW_CTX_DAG_RUN_ID='manual__2024-01-16T10:30:00.071782+00:00'
[2024-01-16T12:30:02.930+0200] {taskinstance.py:2699} ERROR - Task failed with exception
Traceback (most recent call last):
  File "/home/mahmoud/airflow_env/lib/python3.10/site-packages/airflow/models/taskinstance.py", line 433, in _execute_task
    result = execute_callable(context=context, **execute_callable_kwargs)
  File "/home/mahmoud/airflow_env/lib/python3.10/site-packages/airflow/operators/python.py", line 199, in execute
    return_value = self.execute_callable()
  File "/home/mahmoud/airflow_env/lib/python3.10/site-packages/airflow/operators/python.py", line 216, in execute_callable
    return self.python_callable(*self.op_args, **self.op_kwargs)
TypeError: read_csv() missing 1 required positional argument: 'name'
[2024-01-16T12:30:02.933+0200] {taskinstance.py:1138} INFO - Marking task as FAILED. dag_id=execute_python_pipeline, task_id=task_1, execution_date=20240116T103000, start_date=20240116T103002, end_date=20240116T103002
[2024-01-16T12:30:02.946+0200] {standard_task_runner.py:107} ERROR - Failed to execute job 97 for task task_1 (read_csv() missing 1 required positional argument: 'name'; 7800)
[2024-01-16T12:30:02.968+0200] {local_task_job_runner.py:234} INFO - Task exited with return code 1
[2024-01-16T12:30:02.980+0200] {taskinstance.py:3281} INFO - 0 downstream tasks scheduled from follow-on schedule check
