[2024-01-16T12:31:34.103+0200] {taskinstance.py:1957} INFO - Dependencies all met for dep_context=non-requeueable deps ti=<TaskInstance: execute_python_pipeline.task_1 manual__2024-01-16T10:31:31.753836+00:00 [queued]>
[2024-01-16T12:31:34.107+0200] {taskinstance.py:1957} INFO - Dependencies all met for dep_context=requeueable deps ti=<TaskInstance: execute_python_pipeline.task_1 manual__2024-01-16T10:31:31.753836+00:00 [queued]>
[2024-01-16T12:31:34.107+0200] {taskinstance.py:2171} INFO - Starting attempt 1 of 1
[2024-01-16T12:31:34.125+0200] {taskinstance.py:2192} INFO - Executing <Task(PythonOperator): task_1> on 2024-01-16 10:31:31.753836+00:00
[2024-01-16T12:31:34.127+0200] {standard_task_runner.py:60} INFO - Started process 8293 to run task
[2024-01-16T12:31:34.130+0200] {standard_task_runner.py:87} INFO - Running: ['airflow', 'tasks', 'run', 'execute_python_pipeline', 'task_1', 'manual__2024-01-16T10:31:31.753836+00:00', '--job-id', '98', '--raw', '--subdir', 'DAGS_FOLDER/executing_python_pipeline.py', '--cfg-path', '/tmp/tmp02wjqbis']
[2024-01-16T12:31:34.132+0200] {standard_task_runner.py:88} INFO - Job 98: Subtask task_1
[2024-01-16T12:31:34.182+0200] {task_command.py:423} INFO - Running <TaskInstance: execute_python_pipeline.task_1 manual__2024-01-16T10:31:31.753836+00:00 [running]> on host DESKTOP-9NHC01K.
[2024-01-16T12:31:34.252+0200] {taskinstance.py:2481} INFO - Exporting env vars: AIRFLOW_CTX_DAG_OWNER='airflow' AIRFLOW_CTX_DAG_ID='execute_python_pipeline' AIRFLOW_CTX_TASK_ID='task_1' AIRFLOW_CTX_EXECUTION_DATE='2024-01-16T10:31:31.753836+00:00' AIRFLOW_CTX_TRY_NUMBER='1' AIRFLOW_CTX_DAG_RUN_ID='manual__2024-01-16T10:31:31.753836+00:00'
[2024-01-16T12:31:34.253+0200] {taskinstance.py:2699} ERROR - Task failed with exception
Traceback (most recent call last):
  File "/home/mahmoud/airflow_env/lib/python3.10/site-packages/airflow/models/taskinstance.py", line 433, in _execute_task
    result = execute_callable(context=context, **execute_callable_kwargs)
  File "/home/mahmoud/airflow_env/lib/python3.10/site-packages/airflow/operators/python.py", line 199, in execute
    return_value = self.execute_callable()
  File "/home/mahmoud/airflow_env/lib/python3.10/site-packages/airflow/operators/python.py", line 216, in execute_callable
    return self.python_callable(*self.op_args, **self.op_kwargs)
TypeError: read_csv() missing 1 required positional argument: 'name'
[2024-01-16T12:31:34.257+0200] {taskinstance.py:1138} INFO - Marking task as FAILED. dag_id=execute_python_pipeline, task_id=task_1, execution_date=20240116T103131, start_date=20240116T103134, end_date=20240116T103134
[2024-01-16T12:31:34.281+0200] {standard_task_runner.py:107} ERROR - Failed to execute job 98 for task task_1 (read_csv() missing 1 required positional argument: 'name'; 8293)
[2024-01-16T12:31:34.304+0200] {local_task_job_runner.py:234} INFO - Task exited with return code 1
[2024-01-16T12:31:34.313+0200] {taskinstance.py:3281} INFO - 0 downstream tasks scheduled from follow-on schedule check
