[2024-01-22T13:46:28.529+0200] {taskinstance.py:1957} INFO - Dependencies all met for dep_context=non-requeueable deps ti=<TaskInstance: write_to_redshift.create_redshift_table manual__2024-01-22T11:46:26.952802+00:00 [queued]>
[2024-01-22T13:46:28.535+0200] {taskinstance.py:1957} INFO - Dependencies all met for dep_context=requeueable deps ti=<TaskInstance: write_to_redshift.create_redshift_table manual__2024-01-22T11:46:26.952802+00:00 [queued]>
[2024-01-22T13:46:28.536+0200] {taskinstance.py:2171} INFO - Starting attempt 1 of 1
[2024-01-22T13:46:28.571+0200] {taskinstance.py:2192} INFO - Executing <Task(PythonOperator): create_redshift_table> on 2024-01-22 11:46:26.952802+00:00
[2024-01-22T13:46:28.573+0200] {standard_task_runner.py:60} INFO - Started process 33160 to run task
[2024-01-22T13:46:28.575+0200] {standard_task_runner.py:87} INFO - Running: ['airflow', 'tasks', 'run', 'write_to_redshift', 'create_redshift_table', 'manual__2024-01-22T11:46:26.952802+00:00', '--job-id', '240', '--raw', '--subdir', 'DAGS_FOLDER/write_to_redshift.py', '--cfg-path', '/tmp/tmpxxd0jxdb']
[2024-01-22T13:46:28.576+0200] {standard_task_runner.py:88} INFO - Job 240: Subtask create_redshift_table
[2024-01-22T13:46:28.605+0200] {task_command.py:423} INFO - Running <TaskInstance: write_to_redshift.create_redshift_table manual__2024-01-22T11:46:26.952802+00:00 [running]> on host DESKTOP-9NHC01K.
[2024-01-22T13:46:28.665+0200] {taskinstance.py:2481} INFO - Exporting env vars: AIRFLOW_CTX_DAG_OWNER='airflow' AIRFLOW_CTX_DAG_ID='write_to_redshift' AIRFLOW_CTX_TASK_ID='create_redshift_table' AIRFLOW_CTX_EXECUTION_DATE='2024-01-22T11:46:26.952802+00:00' AIRFLOW_CTX_TRY_NUMBER='1' AIRFLOW_CTX_DAG_RUN_ID='manual__2024-01-22T11:46:26.952802+00:00'
[2024-01-22T13:46:28.695+0200] {credentials.py:1278} INFO - Found credentials in shared credentials file: ~/.aws/credentials
[2024-01-22T13:46:30.888+0200] {taskinstance.py:2699} ERROR - Task failed with exception
Traceback (most recent call last):
  File "/home/mahmoud/airflow_env/lib/python3.10/site-packages/airflow/models/taskinstance.py", line 433, in _execute_task
    result = execute_callable(context=context, **execute_callable_kwargs)
  File "/home/mahmoud/airflow_env/lib/python3.10/site-packages/airflow/operators/python.py", line 199, in execute
    return_value = self.execute_callable()
  File "/home/mahmoud/airflow_env/lib/python3.10/site-packages/airflow/operators/python.py", line 216, in execute_callable
    return self.python_callable(*self.op_args, **self.op_kwargs)
  File "/home/mahmoud/airflow/dags/write_to_redshift.py", line 14, in create_table_in_redshift
    response = client.execute_statement(
  File "/home/mahmoud/airflow_env/lib/python3.10/site-packages/botocore/client.py", line 553, in _api_call
    return self._make_api_call(operation_name, kwargs)
  File "/home/mahmoud/airflow_env/lib/python3.10/site-packages/botocore/client.py", line 1009, in _make_api_call
    raise error_class(parsed_response, operation_name)
botocore.errorfactory.ValidationException: An error occurred (ValidationException) when calling the ExecuteStatement operation: Redshift endpoint doesn't exist in this region.
[2024-01-22T13:46:30.893+0200] {taskinstance.py:1138} INFO - Marking task as FAILED. dag_id=write_to_redshift, task_id=create_redshift_table, execution_date=20240122T114626, start_date=20240122T114628, end_date=20240122T114630
[2024-01-22T13:46:30.908+0200] {standard_task_runner.py:107} ERROR - Failed to execute job 240 for task create_redshift_table (An error occurred (ValidationException) when calling the ExecuteStatement operation: Redshift endpoint doesn't exist in this region.; 33160)
[2024-01-22T13:46:30.922+0200] {local_task_job_runner.py:234} INFO - Task exited with return code 1
[2024-01-22T13:46:30.932+0200] {taskinstance.py:3281} INFO - 0 downstream tasks scheduled from follow-on schedule check
