[2024-01-23T17:39:44.819+0200] {taskinstance.py:1957} INFO - Dependencies all met for dep_context=non-requeueable deps ti=<TaskInstance: postgres_to_redshift.load_to_redshift_table scheduled__2024-01-22T00:00:00+00:00 [queued]>
[2024-01-23T17:39:44.824+0200] {taskinstance.py:1957} INFO - Dependencies all met for dep_context=requeueable deps ti=<TaskInstance: postgres_to_redshift.load_to_redshift_table scheduled__2024-01-22T00:00:00+00:00 [queued]>
[2024-01-23T17:39:44.824+0200] {taskinstance.py:2171} INFO - Starting attempt 1 of 1
[2024-01-23T17:39:44.839+0200] {taskinstance.py:2192} INFO - Executing <Task(PythonOperator): load_to_redshift_table> on 2024-01-22 00:00:00+00:00
[2024-01-23T17:39:44.841+0200] {standard_task_runner.py:60} INFO - Started process 44479 to run task
[2024-01-23T17:39:44.844+0200] {standard_task_runner.py:87} INFO - Running: ['airflow', 'tasks', 'run', 'postgres_to_redshift', 'load_to_redshift_table', 'scheduled__2024-01-22T00:00:00+00:00', '--job-id', '277', '--raw', '--subdir', 'DAGS_FOLDER/postgres_to_redshift.py', '--cfg-path', '/tmp/tmp8h491s24']
[2024-01-23T17:39:44.845+0200] {standard_task_runner.py:88} INFO - Job 277: Subtask load_to_redshift_table
[2024-01-23T17:39:44.881+0200] {task_command.py:423} INFO - Running <TaskInstance: postgres_to_redshift.load_to_redshift_table scheduled__2024-01-22T00:00:00+00:00 [running]> on host DESKTOP-9NHC01K.
[2024-01-23T17:39:44.938+0200] {taskinstance.py:2481} INFO - Exporting env vars: AIRFLOW_CTX_DAG_OWNER='airflow' AIRFLOW_CTX_DAG_ID='postgres_to_redshift' AIRFLOW_CTX_TASK_ID='load_to_redshift_table' AIRFLOW_CTX_EXECUTION_DATE='2024-01-22T00:00:00+00:00' AIRFLOW_CTX_TRY_NUMBER='1' AIRFLOW_CTX_DAG_RUN_ID='scheduled__2024-01-22T00:00:00+00:00'
[2024-01-23T17:39:44.943+0200] {taskinstance.py:2699} ERROR - Task failed with exception
Traceback (most recent call last):
  File "/home/mahmoud/airflow_env/lib/python3.10/site-packages/airflow/models/taskinstance.py", line 433, in _execute_task
    result = execute_callable(context=context, **execute_callable_kwargs)
  File "/home/mahmoud/airflow_env/lib/python3.10/site-packages/airflow/operators/python.py", line 199, in execute
    return_value = self.execute_callable()
  File "/home/mahmoud/airflow_env/lib/python3.10/site-packages/airflow/operators/python.py", line 216, in execute_callable
    return self.python_callable(*self.op_args, **self.op_kwargs)
  File "/home/mahmoud/airflow/dags/postgres_to_redshift.py", line 31, in load_data_to_redshift
    for record in records:
TypeError: 'NoneType' object is not iterable
[2024-01-23T17:39:44.954+0200] {taskinstance.py:1138} INFO - Marking task as FAILED. dag_id=postgres_to_redshift, task_id=load_to_redshift_table, execution_date=20240122T000000, start_date=20240123T153944, end_date=20240123T153944
[2024-01-23T17:39:44.969+0200] {standard_task_runner.py:107} ERROR - Failed to execute job 277 for task load_to_redshift_table ('NoneType' object is not iterable; 44479)
[2024-01-23T17:39:44.976+0200] {local_task_job_runner.py:234} INFO - Task exited with return code 1
[2024-01-23T17:39:44.986+0200] {taskinstance.py:3281} INFO - 0 downstream tasks scheduled from follow-on schedule check
