[2024-01-16T12:29:01.393+0200] {taskinstance.py:1957} INFO - Dependencies all met for dep_context=non-requeueable deps ti=<TaskInstance: execute_python_pipeline.task_1 scheduled__2024-01-15T00:00:00+00:00 [queued]>
[2024-01-16T12:29:01.398+0200] {taskinstance.py:1957} INFO - Dependencies all met for dep_context=requeueable deps ti=<TaskInstance: execute_python_pipeline.task_1 scheduled__2024-01-15T00:00:00+00:00 [queued]>
[2024-01-16T12:29:01.398+0200] {taskinstance.py:2171} INFO - Starting attempt 1 of 1
[2024-01-16T12:29:01.415+0200] {taskinstance.py:2192} INFO - Executing <Task(PythonOperator): task_1> on 2024-01-15 00:00:00+00:00
[2024-01-16T12:29:01.418+0200] {standard_task_runner.py:60} INFO - Started process 7303 to run task
[2024-01-16T12:29:01.421+0200] {standard_task_runner.py:87} INFO - Running: ['airflow', 'tasks', 'run', 'execute_python_pipeline', 'task_1', 'scheduled__2024-01-15T00:00:00+00:00', '--job-id', '95', '--raw', '--subdir', 'DAGS_FOLDER/executing_python_pipeline.py', '--cfg-path', '/tmp/tmpuuddk_c6']
[2024-01-16T12:29:01.422+0200] {standard_task_runner.py:88} INFO - Job 95: Subtask task_1
[2024-01-16T12:29:01.459+0200] {task_command.py:423} INFO - Running <TaskInstance: execute_python_pipeline.task_1 scheduled__2024-01-15T00:00:00+00:00 [running]> on host DESKTOP-9NHC01K.
[2024-01-16T12:29:01.521+0200] {taskinstance.py:2481} INFO - Exporting env vars: AIRFLOW_CTX_DAG_OWNER='airflow' AIRFLOW_CTX_DAG_ID='execute_python_pipeline' AIRFLOW_CTX_TASK_ID='task_1' AIRFLOW_CTX_EXECUTION_DATE='2024-01-15T00:00:00+00:00' AIRFLOW_CTX_TRY_NUMBER='1' AIRFLOW_CTX_DAG_RUN_ID='scheduled__2024-01-15T00:00:00+00:00'
[2024-01-16T12:29:01.522+0200] {taskinstance.py:2699} ERROR - Task failed with exception
Traceback (most recent call last):
  File "/home/mahmoud/airflow_env/lib/python3.10/site-packages/airflow/models/taskinstance.py", line 433, in _execute_task
    result = execute_callable(context=context, **execute_callable_kwargs)
  File "/home/mahmoud/airflow_env/lib/python3.10/site-packages/airflow/operators/python.py", line 199, in execute
    return_value = self.execute_callable()
  File "/home/mahmoud/airflow_env/lib/python3.10/site-packages/airflow/operators/python.py", line 216, in execute_callable
    return self.python_callable(*self.op_args, **self.op_kwargs)
TypeError: read_csv() missing 1 required positional argument: 'name'
[2024-01-16T12:29:01.525+0200] {taskinstance.py:1138} INFO - Marking task as FAILED. dag_id=execute_python_pipeline, task_id=task_1, execution_date=20240115T000000, start_date=20240116T102901, end_date=20240116T102901
[2024-01-16T12:29:01.540+0200] {standard_task_runner.py:107} ERROR - Failed to execute job 95 for task task_1 (read_csv() missing 1 required positional argument: 'name'; 7303)
[2024-01-16T12:29:01.554+0200] {local_task_job_runner.py:234} INFO - Task exited with return code 1
[2024-01-16T12:29:01.564+0200] {taskinstance.py:3281} INFO - 0 downstream tasks scheduled from follow-on schedule check
