[2024-01-23T17:43:34.065+0200] {taskinstance.py:1957} INFO - Dependencies all met for dep_context=non-requeueable deps ti=<TaskInstance: postgres_to_redshift.load_to_redshift_table manual__2024-01-23T15:43:29.155250+00:00 [queued]>
[2024-01-23T17:43:34.073+0200] {taskinstance.py:1957} INFO - Dependencies all met for dep_context=requeueable deps ti=<TaskInstance: postgres_to_redshift.load_to_redshift_table manual__2024-01-23T15:43:29.155250+00:00 [queued]>
[2024-01-23T17:43:34.073+0200] {taskinstance.py:2171} INFO - Starting attempt 1 of 1
[2024-01-23T17:43:34.091+0200] {taskinstance.py:2192} INFO - Executing <Task(PythonOperator): load_to_redshift_table> on 2024-01-23 15:43:29.155250+00:00
[2024-01-23T17:43:34.093+0200] {standard_task_runner.py:60} INFO - Started process 45718 to run task
[2024-01-23T17:43:34.095+0200] {standard_task_runner.py:87} INFO - Running: ['airflow', 'tasks', 'run', 'postgres_to_redshift', 'load_to_redshift_table', 'manual__2024-01-23T15:43:29.155250+00:00', '--job-id', '280', '--raw', '--subdir', 'DAGS_FOLDER/postgres_to_redshift.py', '--cfg-path', '/tmp/tmpxk61tpwl']
[2024-01-23T17:43:34.096+0200] {standard_task_runner.py:88} INFO - Job 280: Subtask load_to_redshift_table
[2024-01-23T17:43:34.134+0200] {task_command.py:423} INFO - Running <TaskInstance: postgres_to_redshift.load_to_redshift_table manual__2024-01-23T15:43:29.155250+00:00 [running]> on host DESKTOP-9NHC01K.
[2024-01-23T17:43:34.195+0200] {taskinstance.py:2481} INFO - Exporting env vars: AIRFLOW_CTX_DAG_OWNER='airflow' AIRFLOW_CTX_DAG_ID='postgres_to_redshift' AIRFLOW_CTX_TASK_ID='load_to_redshift_table' AIRFLOW_CTX_EXECUTION_DATE='2024-01-23T15:43:29.155250+00:00' AIRFLOW_CTX_TRY_NUMBER='1' AIRFLOW_CTX_DAG_RUN_ID='manual__2024-01-23T15:43:29.155250+00:00'
[2024-01-23T17:43:34.201+0200] {taskinstance.py:2699} ERROR - Task failed with exception
Traceback (most recent call last):
  File "/home/mahmoud/airflow_env/lib/python3.10/site-packages/airflow/models/taskinstance.py", line 433, in _execute_task
    result = execute_callable(context=context, **execute_callable_kwargs)
  File "/home/mahmoud/airflow_env/lib/python3.10/site-packages/airflow/operators/python.py", line 199, in execute
    return_value = self.execute_callable()
  File "/home/mahmoud/airflow_env/lib/python3.10/site-packages/airflow/operators/python.py", line 216, in execute_callable
    return self.python_callable(*self.op_args, **self.op_kwargs)
  File "/home/mahmoud/airflow/dags/postgres_to_redshift.py", line 31, in load_data_to_redshift
    for record in records:
TypeError: 'NoneType' object is not iterable
[2024-01-23T17:43:34.205+0200] {taskinstance.py:1138} INFO - Marking task as FAILED. dag_id=postgres_to_redshift, task_id=load_to_redshift_table, execution_date=20240123T154329, start_date=20240123T154334, end_date=20240123T154334
[2024-01-23T17:43:34.219+0200] {standard_task_runner.py:107} ERROR - Failed to execute job 280 for task load_to_redshift_table ('NoneType' object is not iterable; 45718)
[2024-01-23T17:43:34.228+0200] {local_task_job_runner.py:234} INFO - Task exited with return code 1
[2024-01-23T17:43:34.240+0200] {taskinstance.py:3281} INFO - 0 downstream tasks scheduled from follow-on schedule check
