[2024-01-22T12:41:44.044+0200] {taskinstance.py:1957} INFO - Dependencies all met for dep_context=non-requeueable deps ti=<TaskInstance: write_to_redshift.create_redshift_table manual__2024-01-22T10:41:41.815822+00:00 [queued]>
[2024-01-22T12:41:44.049+0200] {taskinstance.py:1957} INFO - Dependencies all met for dep_context=requeueable deps ti=<TaskInstance: write_to_redshift.create_redshift_table manual__2024-01-22T10:41:41.815822+00:00 [queued]>
[2024-01-22T12:41:44.049+0200] {taskinstance.py:2171} INFO - Starting attempt 1 of 1
[2024-01-22T12:41:44.067+0200] {taskinstance.py:2192} INFO - Executing <Task(PythonOperator): create_redshift_table> on 2024-01-22 10:41:41.815822+00:00
[2024-01-22T12:41:44.069+0200] {standard_task_runner.py:60} INFO - Started process 14251 to run task
[2024-01-22T12:41:44.073+0200] {standard_task_runner.py:87} INFO - Running: ['airflow', 'tasks', 'run', 'write_to_redshift', 'create_redshift_table', 'manual__2024-01-22T10:41:41.815822+00:00', '--job-id', '225', '--raw', '--subdir', 'DAGS_FOLDER/write_to_redshift.py', '--cfg-path', '/tmp/tmpti63zdp1']
[2024-01-22T12:41:44.074+0200] {standard_task_runner.py:88} INFO - Job 225: Subtask create_redshift_table
[2024-01-22T12:41:44.115+0200] {task_command.py:423} INFO - Running <TaskInstance: write_to_redshift.create_redshift_table manual__2024-01-22T10:41:41.815822+00:00 [running]> on host DESKTOP-9NHC01K.
[2024-01-22T12:41:44.173+0200] {taskinstance.py:2481} INFO - Exporting env vars: AIRFLOW_CTX_DAG_OWNER='airflow' AIRFLOW_CTX_DAG_ID='write_to_redshift' AIRFLOW_CTX_TASK_ID='create_redshift_table' AIRFLOW_CTX_EXECUTION_DATE='2024-01-22T10:41:41.815822+00:00' AIRFLOW_CTX_TRY_NUMBER='1' AIRFLOW_CTX_DAG_RUN_ID='manual__2024-01-22T10:41:41.815822+00:00'
[2024-01-22T12:43:54.986+0200] {taskinstance.py:2699} ERROR - Task failed with exception
Traceback (most recent call last):
  File "/home/mahmoud/airflow_env/lib/python3.10/site-packages/redshift_connector/core.py", line 626, in __init__
    self._usock.connect(hostport)
TimeoutError: [Errno 110] Connection timed out

During handling of the above exception, another exception occurred:

Traceback (most recent call last):
  File "/home/mahmoud/airflow_env/lib/python3.10/site-packages/airflow/models/taskinstance.py", line 433, in _execute_task
    result = execute_callable(context=context, **execute_callable_kwargs)
  File "/home/mahmoud/airflow_env/lib/python3.10/site-packages/airflow/operators/python.py", line 199, in execute
    return_value = self.execute_callable()
  File "/home/mahmoud/airflow_env/lib/python3.10/site-packages/airflow/operators/python.py", line 216, in execute_callable
    return self.python_callable(*self.op_args, **self.op_kwargs)
  File "/home/mahmoud/airflow/dags/write_to_redshift.py", line 26, in create_table_in_redshift
    with redshift_connector.connect(**conn_params) as conn:
  File "/home/mahmoud/airflow_env/lib/python3.10/site-packages/redshift_connector/__init__.py", line 376, in connect
    return Connection(
  File "/home/mahmoud/airflow_env/lib/python3.10/site-packages/redshift_connector/core.py", line 681, in __init__
    raise OperationalError("connection time out", timeout_error)
redshift_connector.error.OperationalError: ('connection time out', TimeoutError(110, 'Connection timed out'))
[2024-01-22T12:43:54.998+0200] {taskinstance.py:1138} INFO - Marking task as FAILED. dag_id=write_to_redshift, task_id=create_redshift_table, execution_date=20240122T104141, start_date=20240122T104144, end_date=20240122T104354
[2024-01-22T12:43:55.023+0200] {standard_task_runner.py:107} ERROR - Failed to execute job 225 for task create_redshift_table (('connection time out', TimeoutError(110, 'Connection timed out')); 14251)
[2024-01-22T12:43:55.052+0200] {local_task_job_runner.py:234} INFO - Task exited with return code 1
[2024-01-22T12:43:55.063+0200] {taskinstance.py:3281} INFO - 0 downstream tasks scheduled from follow-on schedule check
